{
 "cells": [
  {
   "cell_type": "code",
   "execution_count": 1,
   "id": "c9335243-8670-48ea-9db3-d7610383545a",
   "metadata": {},
   "outputs": [],
   "source": [
    "import great_expectations as gx\n",
    "context = gx.get_context()"
   ]
  },
  {
   "cell_type": "code",
   "execution_count": 2,
   "id": "7c071877-0374-4b7e-bc70-bd5c5d8a8efe",
   "metadata": {},
   "outputs": [],
   "source": [
    "PG_CONNECTION_STRING = \"postgresql+psycopg2://postgres:password@10.82.0.37:5432/postgres\"\n",
    "\n",
    "pg_datasource = context.sources.add_sql(\n",
    "    name=\"pg_datasource\", connection_string=PG_CONNECTION_STRING\n",
    ")"
   ]
  },
  {
   "cell_type": "code",
   "execution_count": 4,
   "id": "2e47077d-e8d8-442d-9a20-f3c8d1f9c5d7",
   "metadata": {},
   "outputs": [
    {
     "ename": "TestConnectionError",
     "evalue": "Attempt to connect to table: rusina_test.fct_current_weather failed because the table rusina_test.fct_current_weather does not exist.",
     "output_type": "error",
     "traceback": [
      "\u001b[1;31m---------------------------------------------------------------------------\u001b[0m",
      "\u001b[1;31mTestConnectionError\u001b[0m                       Traceback (most recent call last)",
      "Cell \u001b[1;32mIn[4], line 1\u001b[0m\n\u001b[1;32m----> 1\u001b[0m \u001b[43mpg_datasource\u001b[49m\u001b[38;5;241;43m.\u001b[39;49m\u001b[43madd_table_asset\u001b[49m\u001b[43m(\u001b[49m\n\u001b[0;32m      2\u001b[0m \u001b[43m    \u001b[49m\u001b[43mname\u001b[49m\u001b[38;5;241;43m=\u001b[39;49m\u001b[38;5;124;43m\"\u001b[39;49m\u001b[38;5;124;43mrusina_test.fct_current_weather\u001b[39;49m\u001b[38;5;124;43m\"\u001b[39;49m\u001b[43m,\u001b[49m\u001b[43m \u001b[49m\u001b[43mtable_name\u001b[49m\u001b[38;5;241;43m=\u001b[39;49m\u001b[38;5;124;43m\"\u001b[39;49m\u001b[38;5;124;43mrusina_test.fct_current_weather\u001b[39;49m\u001b[38;5;124;43m\"\u001b[39;49m\n\u001b[0;32m      3\u001b[0m \u001b[43m)\u001b[49m\n",
      "File \u001b[1;32m~\\AppData\\Local\\Packages\\PythonSoftwareFoundation.Python.3.11_qbz5n2kfra8p0\\LocalCache\\local-packages\\Python311\\site-packages\\great_expectations\\datasource\\fluent\\sql_datasource.py:1112\u001b[0m, in \u001b[0;36mSQLDatasource.add_table_asset\u001b[1;34m(self, name, table_name, schema_name, order_by, batch_metadata)\u001b[0m\n\u001b[0;32m   1104\u001b[0m order_by_sorters: \u001b[38;5;28mlist\u001b[39m[Sorter] \u001b[38;5;241m=\u001b[39m \u001b[38;5;28mself\u001b[39m\u001b[38;5;241m.\u001b[39mparse_order_by_sorters(order_by\u001b[38;5;241m=\u001b[39morder_by)\n\u001b[0;32m   1105\u001b[0m asset \u001b[38;5;241m=\u001b[39m \u001b[38;5;28mself\u001b[39m\u001b[38;5;241m.\u001b[39m_TableAsset(\n\u001b[0;32m   1106\u001b[0m     name\u001b[38;5;241m=\u001b[39mname,\n\u001b[0;32m   1107\u001b[0m     table_name\u001b[38;5;241m=\u001b[39mtable_name,\n\u001b[1;32m   (...)\u001b[0m\n\u001b[0;32m   1110\u001b[0m     batch_metadata\u001b[38;5;241m=\u001b[39mbatch_metadata \u001b[38;5;129;01mor\u001b[39;00m {},\n\u001b[0;32m   1111\u001b[0m )\n\u001b[1;32m-> 1112\u001b[0m \u001b[38;5;28;01mreturn\u001b[39;00m \u001b[38;5;28;43mself\u001b[39;49m\u001b[38;5;241;43m.\u001b[39;49m\u001b[43m_add_asset\u001b[49m\u001b[43m(\u001b[49m\u001b[43masset\u001b[49m\u001b[43m)\u001b[49m\n",
      "File \u001b[1;32m~\\AppData\\Local\\Packages\\PythonSoftwareFoundation.Python.3.11_qbz5n2kfra8p0\\LocalCache\\local-packages\\Python311\\site-packages\\great_expectations\\datasource\\fluent\\interfaces.py:549\u001b[0m, in \u001b[0;36mDatasource._add_asset\u001b[1;34m(self, asset, connect_options)\u001b[0m\n\u001b[0;32m    546\u001b[0m     connect_options \u001b[38;5;241m=\u001b[39m {}\n\u001b[0;32m    547\u001b[0m \u001b[38;5;28mself\u001b[39m\u001b[38;5;241m.\u001b[39m_build_data_connector(asset, \u001b[38;5;241m*\u001b[39m\u001b[38;5;241m*\u001b[39mconnect_options)\n\u001b[1;32m--> 549\u001b[0m \u001b[43masset\u001b[49m\u001b[38;5;241;43m.\u001b[39;49m\u001b[43mtest_connection\u001b[49m\u001b[43m(\u001b[49m\u001b[43m)\u001b[49m\n\u001b[0;32m    551\u001b[0m asset_names: Set[\u001b[38;5;28mstr\u001b[39m] \u001b[38;5;241m=\u001b[39m \u001b[38;5;28mself\u001b[39m\u001b[38;5;241m.\u001b[39mget_asset_names()\n\u001b[0;32m    552\u001b[0m \u001b[38;5;28;01mif\u001b[39;00m asset\u001b[38;5;241m.\u001b[39mname \u001b[38;5;129;01min\u001b[39;00m asset_names:\n",
      "File \u001b[1;32m~\\AppData\\Local\\Packages\\PythonSoftwareFoundation.Python.3.11_qbz5n2kfra8p0\\LocalCache\\local-packages\\Python311\\site-packages\\great_expectations\\datasource\\fluent\\sql_datasource.py:904\u001b[0m, in \u001b[0;36mTableAsset.test_connection\u001b[1;34m(self)\u001b[0m\n\u001b[0;32m    895\u001b[0m     \u001b[38;5;28;01mraise\u001b[39;00m TestConnectionError(\n\u001b[0;32m    896\u001b[0m         \u001b[38;5;124mf\u001b[39m\u001b[38;5;124m'\u001b[39m\u001b[38;5;124mAttempt to connect to table: \u001b[39m\u001b[38;5;124m\"\u001b[39m\u001b[38;5;132;01m{\u001b[39;00m\u001b[38;5;28mself\u001b[39m\u001b[38;5;241m.\u001b[39mqualified_name\u001b[38;5;132;01m}\u001b[39;00m\u001b[38;5;124m\"\u001b[39m\u001b[38;5;124m failed because the schema \u001b[39m\u001b[38;5;124m'\u001b[39m\n\u001b[0;32m    897\u001b[0m         \u001b[38;5;124mf\u001b[39m\u001b[38;5;124m'\u001b[39m\u001b[38;5;124m\"\u001b[39m\u001b[38;5;132;01m{\u001b[39;00m\u001b[38;5;28mself\u001b[39m\u001b[38;5;241m.\u001b[39mschema_name\u001b[38;5;132;01m}\u001b[39;00m\u001b[38;5;124m\"\u001b[39m\u001b[38;5;124m does not exist.\u001b[39m\u001b[38;5;124m'\u001b[39m\n\u001b[0;32m    898\u001b[0m     )\n\u001b[0;32m    900\u001b[0m \u001b[38;5;28;01mif\u001b[39;00m \u001b[38;5;129;01mnot\u001b[39;00m inspector\u001b[38;5;241m.\u001b[39mhas_table(\n\u001b[0;32m    901\u001b[0m     table_name\u001b[38;5;241m=\u001b[39m\u001b[38;5;28mself\u001b[39m\u001b[38;5;241m.\u001b[39mtable_name,\n\u001b[0;32m    902\u001b[0m     schema\u001b[38;5;241m=\u001b[39m\u001b[38;5;28mself\u001b[39m\u001b[38;5;241m.\u001b[39mschema_name,\n\u001b[0;32m    903\u001b[0m ):\n\u001b[1;32m--> 904\u001b[0m     \u001b[38;5;28;01mraise\u001b[39;00m TestConnectionError(\n\u001b[0;32m    905\u001b[0m         \u001b[38;5;124mf\u001b[39m\u001b[38;5;124m\"\u001b[39m\u001b[38;5;124mAttempt to connect to table: \u001b[39m\u001b[38;5;132;01m{\u001b[39;00m\u001b[38;5;28mself\u001b[39m\u001b[38;5;241m.\u001b[39mqualified_name\u001b[38;5;132;01m}\u001b[39;00m\u001b[38;5;124m failed because the table\u001b[39m\u001b[38;5;124m\"\u001b[39m\n\u001b[0;32m    906\u001b[0m         \u001b[38;5;124mf\u001b[39m\u001b[38;5;124m\"\u001b[39m\u001b[38;5;124m \u001b[39m\u001b[38;5;132;01m{\u001b[39;00m\u001b[38;5;28mself\u001b[39m\u001b[38;5;241m.\u001b[39mtable_name\u001b[38;5;132;01m}\u001b[39;00m\u001b[38;5;124m does not exist.\u001b[39m\u001b[38;5;124m\"\u001b[39m\n\u001b[0;32m    907\u001b[0m     )\n",
      "\u001b[1;31mTestConnectionError\u001b[0m: Attempt to connect to table: rusina_test.fct_current_weather failed because the table rusina_test.fct_current_weather does not exist."
     ]
    }
   ],
   "source": [
    "pg_datasource.add_table_asset(\n",
    "    name=\"rusina_test.fct_current_weather\", table_name=\"rusina_test.fct_current_weather\"\n",
    ")"
   ]
  },
  {
   "cell_type": "code",
   "execution_count": null,
   "id": "37bac433-9fcf-4f4d-a696-336f26b4c35f",
   "metadata": {},
   "outputs": [],
   "source": []
  }
 ],
 "metadata": {
  "kernelspec": {
   "display_name": "Python 3 (ipykernel)",
   "language": "python",
   "name": "python3"
  },
  "language_info": {
   "codemirror_mode": {
    "name": "ipython",
    "version": 3
   },
   "file_extension": ".py",
   "mimetype": "text/x-python",
   "name": "python",
   "nbconvert_exporter": "python",
   "pygments_lexer": "ipython3",
   "version": "3.11.5"
  }
 },
 "nbformat": 4,
 "nbformat_minor": 5
}
